<?xml version="1.0"?>
<robot xmlns:xacro="http://www.ros.org/wiki/xacro" name="ivastbot">

  <!-- ============================================================ -->
  <!-- Parameters (TODO: đo thực tế và cập nhật)                    -->
  <!-- ============================================================ -->
  <xacro:property name="wheel_separation" value="0.50" />
  <xacro:property name="wheel_radius" value="0.081" />
  <xacro:property name="wheel_width" value="0.05" />
  <xacro:property name="base_length" value="0.60" />
  <xacro:property name="base_width" value="0.40" />
  <xacro:property name="base_height" value="0.15" />

  <!-- ============================================================ -->
  <!-- Base Link                                                     -->
  <!-- ============================================================ -->
  <link name="base_link">
    <visual>
      <geometry>
        <box size="${base_length} ${base_width} ${base_height}" />
      </geometry>
      <origin xyz="0 0 ${base_height/2 + wheel_radius}" rpy="0 0 0" />
      <material name="grey">
        <color rgba="0.5 0.5 0.5 1.0" />
      </material>
    </visual>
    <collision>
      <geometry>
        <box size="${base_length} ${base_width} ${base_height}" />
      </geometry>
      <origin xyz="0 0 ${base_height/2 + wheel_radius}" rpy="0 0 0" />
    </collision>
    <inertial>
      <mass value="20.0" />
      <inertia ixx="0.1" ixy="0" ixz="0" iyy="0.1" iyz="0" izz="0.1" />
    </inertial>
  </link>

  <!-- ============================================================ -->
  <!-- Left Wheel                                                    -->
  <!-- ============================================================ -->
  <link name="left_wheel">
    <visual>
      <geometry>
        <cylinder radius="${wheel_radius}" length="${wheel_width}" />
      </geometry>
      <material name="black">
        <color rgba="0.1 0.1 0.1 1.0" />
      </material>
    </visual>
    <collision>
      <geometry>
        <cylinder radius="${wheel_radius}" length="${wheel_width}" />
      </geometry>
    </collision>
    <inertial>
      <mass value="2.0" />
      <inertia ixx="0.01" ixy="0" ixz="0" iyy="0.01" iyz="0" izz="0.01" />
    </inertial>
  </link>

  <joint name="left_wheel_joint" type="continuous">
    <parent link="base_link" />
    <child link="left_wheel" />
    <origin xyz="0 ${wheel_separation/2} ${wheel_radius}" rpy="${-pi/2} 0 0" />
    <axis xyz="0 0 1" />
  </joint>

  <!-- ============================================================ -->
  <!-- Right Wheel                                                   -->
  <!-- ============================================================ -->
  <link name="right_wheel">
    <visual>
      <geometry>
        <cylinder radius="${wheel_radius}" length="${wheel_width}" />
      </geometry>
      <material name="black">
        <color rgba="0.1 0.1 0.1 1.0" />
      </material>
    </visual>
    <collision>
      <geometry>
        <cylinder radius="${wheel_radius}" length="${wheel_width}" />
      </geometry>
    </collision>
    <inertial>
      <mass value="2.0" />
      <inertia ixx="0.01" ixy="0" ixz="0" iyy="0.01" iyz="0" izz="0.01" />
    </inertial>
  </link>

  <joint name="right_wheel_joint" type="continuous">
    <parent link="base_link" />
    <child link="right_wheel" />
    <origin xyz="0 ${-wheel_separation/2} ${wheel_radius}" rpy="${-pi/2} 0 0" />
    <axis xyz="0 0 1" />
  </joint>

  <!-- ============================================================ -->
  <!-- ros2_control Hardware Interface                               -->
  <!-- ============================================================ -->
  <ros2_control name="IDS830System" type="system">
    <hardware>
      <plugin>ids830_hw/IDS830HW</plugin>
      <param name="can_channel">/dev/ttyACM1</param>
      <param name="serial_baudrate">921600</param>
      <param name="left_motor_id">4</param>
      <param name="right_motor_id">2</param>
      <param name="gear_ratio">1</param>
      <param name="encoder_ppr">2500</param>
      <param name="wheel_radius_m">0.081</param>
      <param name="wheel_track_m">0.50</param>
      <param name="can_speed_code">6</param>
    </hardware>
    <joint name="left_wheel_joint">
      <command_interface name="velocity" />
      <state_interface name="position" />
      <state_interface name="velocity" />
    </joint>
    <joint name="right_wheel_joint">
      <command_interface name="velocity" />
      <state_interface name="position" />
      <state_interface name="velocity" />
    </joint>
  </ros2_control>

</robot>
